Workbook

Sheet Summary
A1: Horus – Dependency licence inventory
A2: Snapshot 24/09/2026, updated 07/10/2026 · prepared for ADR-004 (closed-source licence)
A4: Verdict
A5: Horus can be 100% closed source. No dependency forces us to publish our code: the only blocker, PyMuPDF (AGPL, unused), was removed on 26/09/2026. Everything else is permissive, or copyleft used in a way that leaves our code untouched (separate programs / unmodified libraries), with notice obligations.
A7: Ecosystem | B7: Permissive | C7: Weak copyleft | D7: Strong copyleft | E7: Source-available | F7: Third-party proprietary | G7: Total | H7: Blockers
A8: Python (mas, agent, knowledge-store) | B8: =COUNTIF(Python!$F$2:$F$238,"Permissive") | C8: =COUNTIF(Python!$F$2:$F$238,"Weak copyleft") | D8: =COUNTIF(Python!$F$2:$F$238,"Strong copyleft") | E8: =COUNTIF(Python!$F$2:$F$238,"Source-available") | F8: =COUNTIF(Python!$F$2:$F$238,"Third-party proprietary") | G8: =SUM(B8:F8) | H8: =COUNTIF(Python!$G$2:$G$238,"Blocker*")
A9: Web client (npm lockfile) | B9: =COUNTIF('Web client (npm)'!$F$2:$F$763,"Permissive") | C9: =COUNTIF('Web client (npm)'!$F$2:$F$763,"Weak copyleft") | D9: =COUNTIF('Web client (npm)'!$F$2:$F$763,"Strong copyleft") | E9: =COUNTIF('Web client (npm)'!$F$2:$F$763,"Source-available") | F9: =COUNTIF('Web client (npm)'!$F$2:$F$763,"Third-party proprietary") | G9: =SUM(B9:F9) | H9: =COUNTIF('Web client (npm)'!$G$2:$G$763,"Blocker*")
A10: Desktop (Rust crates + npm) | B10: =COUNTIF('Desktop (Rust + npm)'!$F$2:$F$444,"Permissive") | C10: =COUNTIF('Desktop (Rust + npm)'!$F$2:$F$444,"Weak copyleft") | D10: =COUNTIF('Desktop (Rust + npm)'!$F$2:$F$444,"Strong copyleft") | E10: =COUNTIF('Desktop (Rust + npm)'!$F$2:$F$444,"Source-available") | F10: =COUNTIF('Desktop (Rust + npm)'!$F$2:$F$444,"Third-party proprietary") | G10: =SUM(B10:F10) | H10: =COUNTIF('Desktop (Rust + npm)'!$G$2:$G$444,"Blocker*")
A11: Services & container images | B11: =COUNTIF('Services & images'!$F$2:$F$18,"Permissive") | C11: =COUNTIF('Services & images'!$F$2:$F$18,"Weak copyleft") | D11: =COUNTIF('Services & images'!$F$2:$F$18,"Strong copyleft") | E11: =COUNTIF('Services & images'!$F$2:$F$18,"Source-available") | F11: =COUNTIF('Services & images'!$F$2:$F$18,"Third-party proprietary") | G11: =SUM(B11:F11) | H11: =COUNTIF('Services & images'!$G$2:$G$18,"Blocker*")
A12: AI models | B12: =COUNTIF('AI models'!$D$2:$D$14,"Permissive") | C12: =COUNTIF('AI models'!$D$2:$D$14,"Weak copyleft") | D12: =COUNTIF('AI models'!$D$2:$D$14,"Strong copyleft") | E12: =COUNTIF('AI models'!$D$2:$D$14,"Source-available") | F12: =COUNTIF('AI models'!$D$2:$D$14,"Third-party proprietary") | G12: =SUM(B12:F12) | H12: =COUNTIF('AI models'!$F$2:$F$14,"Blocker*")
A13: Total | B13: =SUM(B8:B12) | C13: =SUM(C8:C12) | D13: =SUM(D8:D12) | E13: =SUM(E8:E12) | F13: =SUM(F8:F12) | G13: =SUM(G8:G12) | H13: =SUM(H8:H12)
A14: Counts are packages, not unique libraries (a package can appear at two versions). The horus-desktop crate itself is our own code and is not counted.
A16: Top actions (details in "Flags & actions")
A17: 1. ✅ PyMuPDF removed from knowledge-store/requirements.txt (26/09): it was the only blocker.
A18: 2. ✅ Redis image replaced by Valkey 9.1.2 (BSD-3-Clause) on 07/10; RedisInsight and pgAdmin only in the dev-tools profile, which the installer never starts.
A19: 3. ✅ THIRD_PARTY_NOTICES generated by scripts/licences/third_party_notices.py (07/10).
A20: 4. Pin versions + add a CI licence gate (fail on AGPL/GPL/SSPL inside our processes).
A21: 5. Before the AI-box rental: check NVIDIA redistribution terms.
A23: Method
A24: Python: requirements files are mostly unpinned, so they were resolved with uv pip compile for Python 3.11 / Linux x86-64 (the Docker base) on 24/09/2026; licences from PyPI metadata. The CPU variant (requirements-cpu.txt) is the same set with the CPU torch wheel and without the NVIDIA packages. spaCy model wheels are listed under AI models.
A25: Web client: package-lock.json (lockfile v3) – every entry, with scope; "shipped" based on the Next.js standalone build.
A26: Desktop: Cargo.lock (all platforms) with licences from crates.io; npm lockfile for the Tauri CLI.
A27: Services: images in src/infra/docker-compose.yml and system packages in the Dockerfiles; licences checked on the upstream LICENSE / vendor pages.
... A29: Not legal advice – an engineering inventory to support the decision.

Sheet Python
A1: Package | B1: Version (resolved) | C1: Services | D1: Direct / transitive | E1: Licence (SPDX) | F1: Category | G1: Compatible with closed Horus? | H1: Obligation / note | I1: Test tooling?
A2: accelerate | B2: 1.15.0 | C2: agent, mas | D2: Direct | E2: Apache-2.0 | F2: Permissive | G2: OK | H2: Keep the copyright + licence text in THIRD_PARTY_NOTICES (Apache-2.0: also reproduce NOTICE files).
A3: agent-detector | B3: 2.0.0 | C3: knowledge-store | D3: Transitive | E3: MIT | F3: Permissive | G3: OK | H3: Keep the copyright + licence text in THIRD_PARTY_NOTICES (Apache-2.0: also reproduce NOTICE files).
A4: aiohappyeyeballs | B4: 2.7.1 | C4: knowledge-store | D4: Transitive | E4: PSF-2.0 | F4: Permissive | G4: OK | H4: Keep the copyright + licence text in THIRD_PARTY_NOTICES (Apache-2.0: also reproduce NOTICE files).
A5: aiohttp | B5: 3.14.3 | C5: knowledge-store | D5: Transitive | E5: Apache-2.0 AND MIT | F5: Permissive | G5: OK | H5: Keep the copyright + licence text in THIRD_PARTY_NOTICES (Apache-2.0: also reproduce NOTICE files).
A6: aiosignal | B6: 1.4.0 | C6: knowledge-store | D6: Transitive | E6: Apache-2.0 | F6: Permissive | G6: OK | H6: Keep the copyright + licence text in THIRD_PARTY_NOTICES (Apache-2.0: also reproduce NOTICE files).
A7: alembic | B7: 1.20.0 | C7: mas | D7: Direct | E7: MIT | F7: Permissive | G7: OK | H7: Keep the copyright + licence text in THIRD_PARTY_NOTICES (Apache-2.0: also reproduce NOTICE files).
A8: annotated-doc | B8: 0.0.5 | C8: agent, knowledge-store, mas | D8: Transitive | E8: MIT | F8: Permissive | G8: OK | H8: Keep the copyright + licence text in THIRD_PARTY_NOTICES (Apache-2.0: also reproduce NOTICE files).
A9: annotated-types | B9: 0.8.0 | C9: agent, knowledge-store, mas | D9: Transitive | E9: MIT | F9: Permissive | G9: OK | H9: Keep the copyright + licence text in THIRD_PARTY_NOTICES (Apache-2.0: also reproduce NOTICE files).
A10: anyio | B10: 4.15.1 | C10: agent, knowledge-store, mas | D10: Transitive | E10: MIT | F10: Permissive | G10: OK | H10: Keep the copyright + licence text in THIRD_PARTY_NOTICES (Apache-2.0: also reproduce NOTICE files).
A11: asgiref | B11: 3.12.1 | C11: knowledge-store, mas | D11: Transitive | E11: BSD-3-Clause | F11: Permissive | G11: OK | H11: Keep the copyright + licence text in THIRD_PARTY_NOTICES (Apache-2.0: also reproduce NOTICE files).
A12: async-timeout | B12: 5.0.1 | C12: agent, mas | D12: Transitive | E12: Apache-2.0 | F12: Permissive | G12: OK | H12: Keep the copyright + licence text in THIRD_PARTY_NOTICES (Apache-2.0: also reproduce NOTICE files).
A13: attrs | B13: 26.1.0 | C13: knowledge-store | D13: Transitive | E13: MIT | F13: Permissive | G13: OK | H13: Keep the copyright + licence text in THIRD_PARTY_NOTICES (Apache-2.0: also reproduce NOTICE files).
... A29: confection | B29: 1.3.3 | C29: agent, knowledge-store | D29: Transitive | E29: MIT | F29: Permissive | G29: OK | H29: Keep the copyright + licence text in THIRD_PARTY_NOTICES (Apache-2.0: also reproduce NOTICE files).
A30: coverage | B30: 7.16.1 | C30: agent, knowledge-store, mas | D30: Transitive | E30: Apache-2.0 | F30: Permissive | G30: OK | H30: Test tool installed in the production image – move to requirements-dev.txt. Keep the copyright + licence text in THIRD_PARTY_NOTICES (Apache-2.0: also reproduce NOTICE files). | I30: Yes
A31: cryptography | B31: 50.0.1 | C31: knowledge-store, mas | D31: Transitive | E31: Apache-2.0 OR BSD-3-Clause | F31: Permissive | G31: OK | H31: Keep the copyright + licence text in THIRD_PARTY_NOTICES (Apache-2.0: also reproduce NOTICE files).
A32: cuda-bindings | B32: 13.4.3 | C32: agent, knowledge-store, mas | D32: Transitive | E32: Apache-2.0 | F32: Permissive | G32: OK | H32: Keep the copyright + licence text in THIRD_PARTY_NOTICES (Apache-2.0: also reproduce NOTICE files).
A33: cuda-pathfinder | B33: 1.8.2 | C33: agent, knowledge-store, mas | D33: Transitive | E33: Apache-2.0 | F33: Permissive | G33: OK | H33: Keep the copyright + licence text in THIRD_PARTY_NOTICES (Apache-2.0: also reproduce NOTICE files).
A34: cuda-toolkit | B34: 13.0.3.0 | C34: agent, knowledge-store, mas | D34: Transitive | E34: NVIDIA proprietary (NVIDIA licence terms) | F34: Third-party proprietary | G34: Review before AI-box launch | H34: NVIDIA licence terms. Today the customer's own install downloads it from PyPI / Docker Hub. When we pre-install it on the rented AI box, check NVIDIA's redistribution terms.
A35: curated-tokenizers | B35: 0.0.10 | C35: agent, knowledge-store | D35: Transitive | E35: MIT | F35: Permissive | G35: OK | H35: Keep the copyright + licence text in THIRD_PARTY_NOTICES (Apache-2.0: also reproduce NOTICE files).
A36: curated-transformers | B36: 0.1.1 | C36: agent, knowledge-store | D36: Transitive | E36: MIT | F36: Permissive | G36: OK | H36: Keep the copyright + licence text in THIRD_PARTY_NOTICES (Apache-2.0: also reproduce NOTICE files).
A37: cymem | B37: 2.0.13 | C37: agent, knowledge-store | D37: Transitive | E37: MIT | F37: Permissive | G37: OK | H37: Keep the copyright + licence text in THIRD_PARTY_NOTICES (Apache-2.0: also reproduce NOTICE files).
A38: detect-installer | B38: 0.2.1 | C38: knowledge-store | D38: Transitive | E38: 0BSD | F38: Permissive | G38: OK | H38: Keep the copyright + licence text in THIRD_PARTY_NOTICES (Apache-2.0: also reproduce NOTICE files).
A39: distro | B39: 1.9.0 | C39: agent, knowledge-store | D39: Transitive | E39: Apache-2.0 | F39: Permissive | G39: OK | H39: Keep the copyright + licence text in THIRD_PARTY_NOTICES (Apache-2.0: also reproduce NOTICE files).
A40: dnspython | B40: 2.8.0 | C40: knowledge-store | D40: Transitive | E40: ISC | F40: Permissive | G40: OK | H40: Keep the copyright + licence text in THIRD_PARTY_NOTICES (Apache-2.0: also reproduce NOTICE files).
A41: durationpy | B41: 0.11 | C41: knowledge-store | D41: Transitive | E41: MIT | F41: Permissive | G41: OK | H41: Keep the copyright + licence text in THIRD_PARTY_NOTICES (Apache-2.0: also reproduce NOTICE files).
A42: ecdsa | B42: 0.19.2 | C42: mas | D42: Transitive | E42: MIT | F42: Permissive | G42: OK | H42: Keep the copyright + licence text in THIRD_PARTY_NOTICES (Apache-2.0: also reproduce NOTICE files).
... A69: importlib-resources | B69: 7.1.0 | C69: knowledge-store | D69: Transitive | E69: Apache-2.0 | F69: Permissive | G69: OK | H69: Keep the copyright + licence text in THIRD_PARTY_NOTICES (Apache-2.0: also reproduce NOTICE files).
A70: iniconfig | B70: 2.3.0 | C70: agent, knowledge-store, mas | D70: Transitive | E70: MIT | F70: Permissive | G70: OK | H70: Test tool installed in the production image – move to requirements-dev.txt. Keep the copyright + licence text in THIRD_PARTY_NOTICES (Apache-2.0: also reproduce NOTICE files). | I70: Yes
A71: itsdangerous | B71: 2.2.0 | C71: knowledge-store | D71: Transitive | E71: BSD-3-Clause | F71: Permissive | G71: OK | H71: Keep the copyright + licence text in THIRD_PARTY_NOTICES (Apache-2.0: also reproduce NOTICE files).
A72: jinja2 | B72: 3.1.6 | C72: agent, knowledge-store, mas | D72: Transitive | E72: BSD-3-Clause | F72: Permissive | G72: OK | H72: Keep the copyright + licence text in THIRD_PARTY_NOTICES (Apache-2.0: also reproduce NOTICE files).
A73: joblib | B73: 1.6.0 | C73: knowledge-store, mas | D73: Transitive | E73: BSD-3-Clause | F73: Permissive | G73: OK | H73: Keep the copyright + licence text in THIRD_PARTY_NOTICES (Apache-2.0: also reproduce NOTICE files).
A74: jsonpatch | B74: 1.33 | C74: agent | D74: Transitive | E74: BSD-3-Clause | F74: Permissive | G74: OK | H74: Keep the copyright + licence text in THIRD_PARTY_NOTICES (Apache-2.0: also reproduce NOTICE files).
A75: jsonpointer | B75: 3.1.1 | C75: agent | D75: Transitive | E75: BSD-3-Clause | F75: Permissive | G75: OK | H75: Keep the copyright + licence text in THIRD_PARTY_NOTICES (Apache-2.0: also reproduce NOTICE files).
A76: jsonschema | B76: 4.26.0 | C76: knowledge-store | D76: Transitive | E76: MIT | F76: Permissive | G76: OK | H76: Keep the copyright + licence text in THIRD_PARTY_NOTICES (Apache-2.0: also reproduce NOTICE files).
A77: jsonschema-specifications | B77: 2025.9.1 | C77: knowledge-store | D77: Transitive | E77: MIT | F77: Permissive | G77: OK | H77: Keep the copyright + licence text in THIRD_PARTY_NOTICES (Apache-2.0: also reproduce NOTICE files).
A78: kubernetes | B78: 36.0.3 | C78: knowledge-store | D78: Transitive | E78: Apache-2.0 | F78: Permissive | G78: OK | H78: Keep the copyright + licence text in THIRD_PARTY_NOTICES (Apache-2.0: also reproduce NOTICE files).
A79: langchain | B79: 1.4.2 | C79: agent | D79: Direct | E79: MIT | F79: Permissive | G79: OK | H79: Keep the copyright + licence text in THIRD_PARTY_NOTICES (Apache-2.0: also reproduce NOTICE files).
A80: langchain-core | B80: 1.6.4 | C80: agent | D80: Direct | E80: MIT | F80: Permissive | G80: OK | H80: Keep the copyright + licence text in THIRD_PARTY_NOTICES (Apache-2.0: also reproduce NOTICE files).
A81: langchain-protocol | B81: 0.0.19 | C81: agent | D81: Transitive | E81: MIT | F81: Permissive | G81: OK | H81: Keep the copyright + licence text in THIRD_PARTY_NOTICES (Apache-2.0: also reproduce NOTICE files).
...

Sheet Web client (npm)
A1: Package | B1: Version | C1: Scope in lockfile | D1: Shipped in the web-client image? | E1: Licence (SPDX) | F1: Category | G1: Compatible with closed Horus? | H1: Obligation / note
A2: @adobe/css-tools | B2: 4.4.4 | C2: dev | D2: No – build/test time only | E2: MIT | F2: Permissive | G2: OK | H2: Keep the copyright + licence text in THIRD_PARTY_NOTICES (Apache-2.0: also reproduce NOTICE files).
A3: @alloc/quick-lru | B3: 5.2.0 | C3: dev | D3: No – build/test time only | E3: MIT | F3: Permissive | G3: OK | H3: Keep the copyright + licence text in THIRD_PARTY_NOTICES (Apache-2.0: also reproduce NOTICE files).
A4: @asamuzakjp/css-color | B4: 3.2.0 | C4: dev | D4: No – build/test time only | E4: MIT | F4: Permissive | G4: OK | H4: Keep the copyright + licence text in THIRD_PARTY_NOTICES (Apache-2.0: also reproduce NOTICE files).
A5: lru-cache | B5: 10.4.3 | C5: dev | D5: No – build/test time only | E5: ISC | F5: Permissive | G5: OK | H5: Keep the copyright + licence text in THIRD_PARTY_NOTICES (Apache-2.0: also reproduce NOTICE files).
A6: @babel/code-frame | B6: 7.28.6 | C6: dev | D6: No – build/test time only | E6: MIT | F6: Permissive | G6: OK | H6: Keep the copyright + licence text in THIRD_PARTY_NOTICES (Apache-2.0: also reproduce NOTICE files).
A7: @babel/compat-data | B7: 7.28.6 | C7: dev | D7: No – build/test time only | E7: MIT | F7: Permissive | G7: OK | H7: Keep the copyright + licence text in THIRD_PARTY_NOTICES (Apache-2.0: also reproduce NOTICE files).
A8: @babel/core | B8: 7.28.6 | C8: dev | D8: No – build/test time only | E8: MIT | F8: Permissive | G8: OK | H8: Keep the copyright + licence text in THIRD_PARTY_NOTICES (Apache-2.0: also reproduce NOTICE files).
A9: convert-source-map | B9: 2.0.0 | C9: dev | D9: No – build/test time only | E9: MIT | F9: Permissive | G9: OK | H9: Keep the copyright + licence text in THIRD_PARTY_NOTICES (Apache-2.0: also reproduce NOTICE files).
A10: @babel/generator | B10: 7.28.6 | C10: dev | D10: No – build/test time only | E10: MIT | F10: Permissive | G10: OK | H10: Keep the copyright + licence text in THIRD_PARTY_NOTICES (Apache-2.0: also reproduce NOTICE files).
A11: @babel/helper-compilation-targets | B11: 7.28.6 | C11: dev | D11: No – build/test time only | E11: MIT | F11: Permissive | G11: OK | H11: Keep the copyright + licence text in THIRD_PARTY_NOTICES (Apache-2.0: also reproduce NOTICE files).
A12: @babel/helper-globals | B12: 7.28.0 | C12: dev | D12: No – build/test time only | E12: MIT | F12: Permissive | G12: OK | H12: Keep the copyright + licence text in THIRD_PARTY_NOTICES (Apache-2.0: also reproduce NOTICE files).
... A763: zwitch | B763: 2.0.4 | C763: prod | D763: Yes – bundled into the app JS | E763: MIT | F763: Permissive | G763: OK | H763: Keep the copyright + licence text in THIRD_PARTY_NOTICES (Apache-2.0: also reproduce NOTICE files).

Sheet Desktop (Rust + npm)
A1: Package | B1: Version | C1: Ecosystem | D1: Shipped? | E1: Licence (SPDX) | F1: Category | G1: Compatible with closed Horus? | H1: Obligation / note
A2: adler2 | B2: 2.0.1 | C2: Rust | D2: Compiled into the desktop binary (per platform) | E2: 0BSD OR MIT OR Apache-2.0 | F2: Permissive | G2: OK | H2: Keep the copyright + licence text in THIRD_PARTY_NOTICES (Apache-2.0: also reproduce NOTICE files).
A3: aho-corasick | B3: 1.1.5 | C3: Rust | D3: Compiled into the desktop binary (per platform) | E3: Unlicense OR MIT | F3: Permissive | G3: OK | H3: Keep the copyright + licence text in THIRD_PARTY_NOTICES (Apache-2.0: also reproduce NOTICE files).
A4: alloc-no-stdlib | B4: 2.0.4 | C4: Rust | D4: Compiled into the desktop binary (per platform) | E4: BSD-3-Clause | F4: Permissive | G4: OK | H4: Keep the copyright + licence text in THIRD_PARTY_NOTICES (Apache-2.0: also reproduce NOTICE files).
A5: alloc-stdlib | B5: 0.2.4 | C5: Rust | D5: Compiled into the desktop binary (per platform) | E5: BSD-3-Clause | F5: Permissive | G5: OK | H5: Keep the copyright + licence text in THIRD_PARTY_NOTICES (Apache-2.0: also reproduce NOTICE files).
A6: android_system_properties | B6: 0.1.6 | C6: Rust | D6: Compiled into the desktop binary (per platform) | E6: MIT OR Apache-2.0 | F6: Permissive | G6: OK | H6: Keep the copyright + licence text in THIRD_PARTY_NOTICES (Apache-2.0: also reproduce NOTICE files).
A7: anyhow | B7: 1.0.104 | C7: Rust | D7: Compiled into the desktop binary (per platform) | E7: MIT OR Apache-2.0 | F7: Permissive | G7: OK | H7: Keep the copyright + licence text in THIRD_PARTY_NOTICES (Apache-2.0: also reproduce NOTICE files).
A8: atk | B8: 0.18.2 | C8: Rust | D8: Compiled into the desktop binary (per platform) | E8: MIT | F8: Permissive | G8: OK | H8: Keep the copyright + licence text in THIRD_PARTY_NOTICES (Apache-2.0: also reproduce NOTICE files).
A9: atk-sys | B9: 0.18.2 | C9: Rust | D9: Compiled into the desktop binary (per platform) | E9: MIT | F9: Permissive | G9: OK | H9: Keep the copyright + licence text in THIRD_PARTY_NOTICES (Apache-2.0: also reproduce NOTICE files).
A10: atomic-waker | B10: 1.1.2 | C10: Rust | D10: Compiled into the desktop binary (per platform) | E10: Apache-2.0 OR MIT | F10: Permissive | G10: OK | H10: Keep the copyright + licence text in THIRD_PARTY_NOTICES (Apache-2.0: also reproduce NOTICE files).
A11: autocfg | B11: 1.5.1 | C11: Rust | D11: Compiled into the desktop binary (per platform) | E11: Apache-2.0 OR MIT | F11: Permissive | G11: OK | H11: Keep the copyright + licence text in THIRD_PARTY_NOTICES (Apache-2.0: also reproduce NOTICE files).
A12: base64 | B12: 0.21.7 | C12: Rust | D12: Compiled into the desktop binary (per platform) | E12: MIT OR Apache-2.0 | F12: Permissive | G12: OK | H12: Keep the copyright + licence text in THIRD_PARTY_NOTICES (Apache-2.0: also reproduce NOTICE files).
... A444: @tauri-apps/cli-win32-x64-msvc | B444: 2.11.4 | C444: npm | D444: No – build tool (Tauri CLI) | E444: Apache-2.0 OR MIT | F444: Permissive | G444: OK | H444: Build-time only, not distributed.

Sheet Services & images
A1: Component | B1: Image / package | C1: Role in Horus | D1: How Horus uses it | E1: Licence | F1: Category | G1: Compatible with closed Horus? | H1: Obligation / action
A2: RabbitMQ | B2: rabbitmq:4.1.2-management | C2: Message broker (MAS ↔ agents) | D2: Separate container, unmodified, AMQP | E2: MPL-2.0 | F2: Weak copyleft | G2: OK – conditions | H2: Keep unmodified; ship licence text + source link.
A3: vLLM | B3: vllm/vllm-openai:v0.23.0 | C3: GPU inference server (GPU profile) | D3: Separate container, OpenAI-compatible HTTP API | E3: Apache-2.0 (image also contains NVIDIA CUDA under NVIDIA terms) | F3: Permissive | G3: OK | H3: Keep NOTICE. The CUDA libraries in the image fall under NVIDIA terms – review before pre-installing on the rented AI box.
A4: llama.cpp server | B4: ghcr.io/ggml-org/llama.cpp:server-b11382 | C4: CPU inference server (CPU profiles) | D4: Separate container (services llm and llm-model), OpenAI-compatible HTTP API | E4: MIT | F4: Permissive | G4: OK | H4: Keep notice (Copyright (c) 2023-2026 The ggml authors).
A5: NVIDIA CUDA base image | B5: nvidia/cuda:12.4.0-base-ubuntu22.04 | C5: GPU check run once by the installer | D5: docker run --gpus all ... nvidia-smi; not part of the stack | E5: NVIDIA Deep Learning Container License | F5: Third-party proprietary | G5: OK – conditions | H5: Pulled on the user's machine only to test the GPU; Horus does not redistribute it.
A6: PostgreSQL | B6: postgres:18.6 | C6: Main database | D6: Separate container | E6: PostgreSQL License | F6: Permissive | G6: OK | H6: Pinned to 18.6, the version latest gave on 07/10/2026.
A7: Valkey | B7: valkey/valkey:9.1.2 | C7: Cache (Compose service redis) | D7: Separate container, unmodified | E7: BSD-3-Clause | F7: Permissive | G7: OK | H7: Keep notice. Replaced redis:7 (Redis 7.4, RSALv2 or SSPLv1) on 07/10/2026; same protocol, redis-py unchanged.
A8: pgAdmin | B8: dpage/pgadmin4:9.18.0 | C8: DB admin UI (dev-tools profile) | D8: Separate container | E8: PostgreSQL License | F8: Permissive | G8: OK | H8: Licence OK. Development tool only: Compose profile dev-tools, which the installer never starts (admin UI with default credentials).
A9: RedisInsight | B9: redis/redisinsight:3.8.0 | C9: Cache admin UI (dev-tools profile) | D9: Separate container | E9: SSPL-1.0 | F9: Source-available | G9: Do not ship to customers | H9: Team/debug tool only: Compose profile dev-tools, which the installer never starts, so it is not in a customer install.
A10: Grafana Loki | B10: grafana/loki:3.4.2 | C10: Log storage (/admin/logs) | D10: Separate container, unmodified, HTTP API only | E10: AGPL-3.0-only | F10: Strong copyleft | G10: OK – conditions | H10: Does not make Horus AGPL: it is a separate program we talk to over HTTP. Conditions: never modify or fork it; ship the AGPL text + link to the exact upstream source. If a customer's policy bans AGPL, swap for an Apache-licensed store.
A11: Grafana Tempo | B11: grafana/tempo:2.6.0 | C11: Traces (/admin/traces) | D11: Separate container, unmodified, HTTP/OTLP | E11: AGPL-3.0-only | F11: Strong copyleft | G11: OK – conditions | H11: Same as Loki. Alternative if needed: Jaeger (Apache-2.0).
A12: Promtail | B12: grafana/promtail:3.4.2 | C12: Ships container logs to Loki | D12: Separate container | E12: Apache-2.0 (Loki clients/ folder) | F12: Permissive | G12: OK | H12: Licence OK, but Promtail reached end of life in March 2026 – migrate to Grafana Alloy (Apache-2.0).
... A18: build-essential / g++ | B18: Debian packages in mas image | C18: Compilers left in the final image | D18: Build tools (single-stage Dockerfile) | E18: GPL-3.0 with GCC Runtime Library Exception | F18: Strong copyleft | G18: OK – conditions | H18: Runtime-library exception covers compiled output. Better: multi-stage build so compilers are not shipped (smaller, fewer licences to declare).

Sheet AI models
A1: Model | B1: Used by | C1: Licence | D1: Category | E1: Commercial use? | F1: Compatible with closed Horus? | G1: Obligation / action | H1: Source checked
A2: Qwen/Qwen2.5-1.5B-Instruct | B2: MAS router (3.1 GB, CPU) | C2: Apache-2.0 | D2: Permissive | E2: Yes | F2: OK | G2: Ship licence + attribution with the model files. | H2: huggingface.co/Qwen/Qwen2.5-1.5B-Instruct
A3: Qwen/Qwen3-4B-Instruct-2507 | B3: Agent generation (transformers) | C3: Apache-2.0 | D3: Permissive | E3: Yes | F3: OK | G3: Ship licence + attribution. | H3: huggingface.co/Qwen/Qwen3-4B-Instruct-2507
A4: warshanks/Qwen3-4B-Instruct-2507-AWQ | B4: vLLM default (GPU profile) | C4: Apache-2.0 | D4: Permissive | E4: Yes | F4: OK – conditions | G4: Community re-upload by an individual (base: Qwen3-4B-Instruct-2507). Pin a commit revision, keep its licence file, or produce our own AWQ quant from the official weights. | H4: huggingface.co/warshanks/Qwen3-4B-Instruct-2507-AWQ
A5: unsloth/Qwen3-4B-Instruct-2507-GGUF (Q4_K_M) | B5: llama-server, CPU profiles (cpu-standard, cpu-lean); downloaded by the installer from models/manifest.json | C5: Apache-2.0 | D5: Permissive | E5: Yes | F5: OK | G5: Ship licence + attribution (base model Qwen/Qwen3-4B-Instruct-2507). Revision pinned in models/manifest.json. | H5: huggingface.co/unsloth/Qwen3-4B-Instruct-2507-GGUF
A6: BAAI/bge-base-en-v1.5 | B6: Knowledge-store embeddings | C6: MIT | D6: Permissive | E6: Yes | F6: OK | G6: Keep notice. | H6: huggingface.co/BAAI/bge-base-en-v1.5
A7: Qdrant/bge-base-en-v1.5-onnx-Q | B7: Knowledge-store embeddings: the ONNX export fastembed downloads for BAAI/bge-base-en-v1.5 | C7: MIT | D7: Permissive | E7: Yes | F7: OK | G7: Keep notice. | H7: huggingface.co/Qdrant/bge-base-en-v1.5-onnx-Q
A8: sentence-transformers/all-MiniLM-L6-v2 | B8: MAS embeddings | C8: Apache-2.0 | D8: Permissive | E8: Yes | F8: OK | G8: Keep notice. | H8: huggingface.co/sentence-transformers/all-MiniLM-L6-v2
A9: Qdrant/all-MiniLM-L6-v2-onnx | B9: MAS embeddings: the ONNX export fastembed downloads for all-MiniLM-L6-v2 | C9: Apache-2.0 | D9: Permissive | E9: Yes | F9: OK | G9: Keep notice. | H9: huggingface.co/Qdrant/all-MiniLM-L6-v2-onnx
A10: spaCy en_core_web_trf 3.8.0 | B10: NER in agent + knowledge-store | C10: MIT | D10: Permissive | E10: Yes | F10: OK | G10: Keep notice. | H10: huggingface.co/spacy/en_core_web_trf
A11: spaCy en_core_web_sm 3.8.0 | B11: NER in agent | C11: MIT | D11: Permissive | E11: Yes | F11: OK | G11: Keep notice. | H11: huggingface.co/spacy/en_core_web_sm
A12: google-t5/t5-small | B12: Knowledge-store ContentAnalyzer: classification fallback (content_analyzer.py) | C12: Apache-2.0 | D12: Permissive | E12: Yes | F12: OK | G12: Keep licence + attribution. | H12: huggingface.co/google-t5/t5-small
... A14: sshleifer/distilbart-cnn-12-6 | B14: Agent summarizer_tool: pipeline("summarization") with no model set → transformers default | C14: Apache-2.0 | D14: Permissive | E14: Yes | F14: OK – conditions | G14: Downloaded implicitly as the transformers default: pin it explicitly (model id + revision) so it cannot change silently. | H14: huggingface.co/sshleifer/distilbart-cnn-12-6; transformers 4.57 pipelines default

Sheet Flags & actions
A1: # | B1: Priority | C1: Item | D1: Where | E1: Licence | F1: Why it matters | G1: Action | H1: Effort | I1: Status
A2: 1 | B2: Done | C2: PyMuPDF 1.25.4 | D2: knowledge-store/requirements.txt | E2: AGPL-3.0 (or paid Artifex licence) | F2: The only dependency that could force us to publish code: an AGPL library imported in-process makes the knowledge-store AGPL for everyone who receives it. It is installed but not imported anywhere in src/ (checked 24/09). | G2: Removed from requirements.txt on 26/09/2026 (no import anywhere; pdfplumber + pypdfium2 cover PDF parsing). Row kept as a record. | H2: 5 min | I2: Done (26/09)
A3: 2 | B3: Done | C3: Redis image (redis:7 → 7.4.x) | D3: src/infra/docker-compose.yml | E3: RSALv2 / SSPLv1 | F3: Allowed for our use, but not open source; enterprise customers' legal teams often flag it, and the floating tag changed licence once already (7.4). | G3: Replaced by valkey/valkey:9.1.2 (BSD-3-Clause); service name and REDIS_* settings unchanged. | H3: 1–2 h + tests | I3: Done (07/10)
A4: 3 | B4: Done | C4: RedisInsight | D4: src/infra/docker-compose.yml (dev-tools profile) | E4: SSPL-1.0 | F4: Source-available licence; also an admin UI. | G4: RedisInsight and pgAdmin moved to the Compose profile dev-tools; the installer never starts it and no longer checks their ports. | H4: 15 min | I4: Done (07/10)
A5: 4 | B5: Done | C5: Third-party notices | D5: Whole distribution | E5: MIT / BSD / Apache-2.0 / MPL / LGPL / GPL / AGPL | F5: Almost every licence we use requires keeping the copyright + licence text in what we distribute; Apache-2.0 NOTICE files must be reproduced; copyleft components need a "where to get the source" line. | G5: THIRD_PARTY_NOTICES at the repo root, generated by scripts/licences/third_party_notices.py (--check fails when it is out of date). | H5: 0.5 day | I5: Done (07/10)
A6: 5 | B6: Medium | C6: Unpinned versions | D6: requirements*.txt, compose images (latest, redis:7) | E6: — | F6: This inventory is a resolution as of 24/09/2026; unpinned packages and floating tags can change version and licence without anyone noticing. | G6: Pin versions (uv pip compile → lock files), pin image tags, and add a CI licence gate that fails on AGPL/GPL/SSPL inside our processes. | H6: 0.5 day | I6: To do
A7: 6 | B7: Low | C7: Grafana Loki + Tempo | D7: src/infra/docker-compose.yml | E7: AGPL-3.0-only | F7: Fine as separate unmodified containers, but must never be modified/forked, and some customers ban AGPL outright. | G7: Keep unmodified; list in notices with source links; keep Jaeger (Apache-2.0) as a fallback option. | H7: — | I7: Accepted
A8: 7 | B8: Low | C8: poppler-utils | D8: knowledge-store image | E8: GPL-2.0 / GPL-3.0 | F8: Separate program → aggregation, our code unaffected; needs GPL text + source offer. | G8: Keep as separate process + notice, or replace pdf2image with pypdfium2 rendering (removes GPL from the image). | H8: 2 h | I8: Optional
A9: 8 | B9: Low | C9: LGPL / MPL libraries | D9: psycopg2-binary, sharp/libvips, certifi, tqdm, orjson, 5 Rust crates | E9: LGPL-3.0 / MPL-2.0 | F9: Allowed in closed software when used unmodified; obligations are notices + source location. | G9: Never patch these in place; list them in notices. | H9: — | I9: Accepted
A10: 9 | B10: Low | C10: NVIDIA CUDA libraries | D10: nvidia-* wheels, vLLM image | E10: NVIDIA licence terms | F10: Today the customer's install downloads them. The rented AI box (pitch, slide 6) means we pre-install = we redistribute. | G10: Read NVIDIA's redistribution terms (CUDA / cuDNN / DGX Spark software) before the AI-box offer launches. | H10: 1 h | I10: Before AI box
A11: 10 | B11: Low | C11: Community AWQ model | D11: vLLM default model | E11: Apache-2.0 | F11: Uploaded by an individual; could change or disappear. | G11: Pin a revision hash, or quantise the official Qwen weights ourselves. | H11: 1 h | I11: Optional
A12: 11 | B12: Low | C12: Promtail end of life | D12: src/infra/docker-compose.yml | E12: Apache-2.0 | F12: Not a licence issue: EOL since March 2026, no more security fixes. | G12: Migrate to Grafana Alloy (Apache-2.0). | H12: 0.5 day | I12: Optional
A13: 12 | B13: Low | C13: Test tools in production images | D13: mas / agent / knowledge-store requirements | E13: MIT / MPL-2.0 | F13: pytest, pytest-html (MPL) etc. ship to customers for no reason. | G13: Move to requirements-dev.txt. | H13: 30 min | I13: Optional

Sheet Legend
A1: Category | B1: What it means | C1: Effect on a closed-source Horus
A2: Permissive | B2: MIT, BSD, Apache-2.0, ISC, Zlib, Unicode-3.0, PSF, 0BSD, Unlicense, CC0, BSL-1.0 (Boost), PostgreSQL. Dual licences with a permissive option (e.g. "MIT OR Apache-2.0", "MIT OR Apache-2.0 OR LGPL-2.1") count as permissive: we pick the permissive one. | C2: None on our code. Keep copyright + licence text; Apache-2.0 also asks to reproduce NOTICE files and mark modified files.
A3: Weak copyleft | B3: LGPL (library-level), MPL-2.0 (file-level). | C3: None on our code if used unmodified / dynamically. Modified MPL files must be published; LGPL libraries must stay replaceable. Ship licence + source location.
A4: Strong copyleft | B4: GPL, AGPL. | C4: Blocker if linked/imported into our process (our code would have to be released under the same licence). OK as a separate, unmodified program we call over a process boundary or network (aggregation) – with licence text + source offer.
A5: Source-available | B5: RSALv2, SSPL, BUSL, Elastic 2.0 – source is visible but the licence is not open source and restricts some uses. | C5: Read each one. RSALv2 allows use inside our product; SSPL targets offering the software as a service. Enterprise legal teams often flag these.
A6: Third-party proprietary | B6: Vendor licences, e.g. NVIDIA CUDA libraries. | C6: Follow the vendor terms, especially when we redistribute (AI box).
A7: Own code | B7: Horus code. | C7: Proprietary – see ADR-004.
A10: Not legal advice.
A11: This is an engineering inventory to prepare the decision. Have a lawyer review the commercial licence and the notices before the first paid contract.
